Workbook

Sheet Page 1
C1: PERSONAL FINANCIAL STATEMENT AS OF
C2: Commercial Mortgage Depot
C3: 1000 Clifton Ave., Suite 104, Clifton, NJ 07013
C4: Phone: (973) 742-1111 | G4: Fax: (973) 742-8899
A6: Personal Information
A7: Applicant Name | G7: Co-Applicant Name
A9: Home Address | G9: Home Address
A12: Home Phone No. | C12: Social Security No. | E12: Date of Birth | G12: Home Phone No. | I12: Social Security No. | K12: Date of Birth
A14: Employer | G14: Employer
A16: Address of Employer | G16: Address of Employer
A19: Business No. | C19: Years | E19: Title/Position | G19: Business No. | I19: Years | K19: Title/Position
A21: Name and Phone No. of your Accountant | G21: Name and Phone No. of your Accountant
A23: Attorney Contact | G23: Attorney Contact
A25: Investment Advisor/Broker Contact | G25: Investment Advisor/Broker Contact
A27: Insurance Advisor Contact | G27: Insurance Advisor Contact
A30: Income and Expenses
A31: Annual Income | E31: Amount ($) | G31: Annual Expense | K31: Amount ($)
A32: Salary (Applicant) | G32: Federal Income Taxes
A33: Salary (Co-Applicant) | G33: State Income Taxes
A34: Bonuses and Commissions (Applicant) | G34: Other Taxes
A35: Bonuses and Commissions (Co) | G35: MTG Payments (Resi PAGE 3) | K35: ='Page 3'!I24*12 -> 16376.76
A36: Rental Income (PAGE 6) | E36: ='Page 6'!M46*12 -> 31980 | G36: MTG Payments (Invest PAGE 6) | K36: ='Page 6'!N46*12 -> 96
A37: Interest Income | G37: Property Taxes (Residential)
A38: Dividend Income | G38: Property Taxes (Investment) | K38: ='Page 6'!P45 -> 14509
A39: Capital Gains | G39: P&I Payments on Loans
A40: Partnership Income | G40: Rental Payments, Condo Maint
A41: Other Investment Income | G41: Insurance Premiums | K41: ='Page 6'!P46 -> 2018
G42: Investments (Incl tax shelters)
A43: Other Income (list)** | G43: Alimony/Child Support
G44: Tuition
G45: Medical Expenses
G46: Other Living Expenses
G47: Other Expenses (list)
D51: Total Income | E51: =SUM(E32:F50) -> 31980 | J51: Total Expense | K51: =SUM(K32:L50) -> 32999.76
B52: Do you anticipate any significant changes within the next 12 months? □ Yes □ No (If yes, attach explanation).
B54: **Income from alimony, child support, or separate maintenance payments need not be revealed if the applicant or co-applicant does not wish to have them considered as a basis for repaying a loan

Sheet Page 2
A1: **Where there is a "0" in place there are formulas tieing in from sub-schedules. Please follow directions on first page and input onto the supporting schedules 1st.
A2: **Balance Sheet (omit cents)
A3: Assets | E3: Amount ($) | G3: Liabilities | K3: Amount ($)
A4: Checking | G4: Notes payable to this bank
A5: Checking | G5: Secured
A6: Savings | G6: Unsecured
A7: Savings CD | E7: 50 | G7: Notes Payable to Others | K7: 10
G8: Secured
G9: Unsecured
A10: Readily Marketable Securities (Sched A) | E10: =I51 -> 0 | G10: Credit Cards
A11: Non-Readily Marketable Securities (Sched A) | E11: =I56 -> 0 | G11: Accounts Payable (Sched E) | K11: ='Page 4'!I10 -> 0
A12: Accounts and Notes Receivable | G12: Margin Accounts
A13: Cash Value of Life Insurance (Sched B) | E13: ='Page 3'!G8 -> 0 | G13: Life Insurance Loans (Sched B) | K13: ='Page 3'!I8 -> 0
A14: Residential Real Estate (Sched C) | E14: =SUM('Page 3'!E24) -> 0 | G14: Residentail Mortgage Debt (Sched C) | K14: =SUM('Page 3'!F24) -> 0
A15: Real Estate Investments (Sched C) | E15: ='Page 6'!H46 -> 200000 | G15: RE investments Mortgage Debt (Sched C) | K15: =SUM('Page 6'!I46) -> 0
A16: Partnership Interests (Sched D) | E16: ='Page 3'!F50 -> 0 | G16: Notes Due Partnerships (Sched D) | K16: ='Page 3'!H50 -> 0
A17: Retirement Accounts (vested) | G17: Taxes Payable
A18: Deferred Income (No. of yrs deferred ____) | G18: Other Liabilities (list)
A19: Personal Property
A20: Autos
A21: Other Assets (list)
I26: Total Liabilities | K26: =SUM(K4:L25) -> 10
I27: Net Worth | K27: =E28-K26 -> 200040
C28: Total Assets | E28: =SUM(E4:F27) -> 200050 | G28: = | H28: Total Liabilities & Net Worth | K28: =SUM(K26:L27) -> 200050
A30: Do you anticipate any significant changes in your Income and Expense Statement or Balance Sheet within the next 12 months?
F31: (if YES, please attach separate explanation) | K31: (no)
A33: Contingent Liabilities
I34: Yes | J34: No | K34: Amount($)
A35: Are you a guarantor, co-borrower, or endorser for any debt of any ind, corp or partner?
A36: Do you have any outstanding letters of credit or surety bonds?
A37: Are there any suits or legal actions pending against you?
A38: Are you contingently liable on any lease or contract?
A39: Are any of your tax obligations past due? | K39: 0
A40: What would be your total estimated tax liability if you were to sell your major assets? | J40: 0
A41: If answer is yes for any of the above please attach additional details
A43: Schedule A - All Securities (including non-money market mutual funds)
A44: No of Shares | B44: Description | E44: Owner | F44: Where Held | G44: Cost | I44: Current Market Value | K44: Pledged?
K45: Yes | L45: No
A46: Readily Marketable Securities (including U.S. Governments and Municipals)
I51: =SUM(I47:J50) -> 0
...

Sheet Page 3
A1: Schedule B - Insurance
A2: Insurance Company | B2: Face Amt of Policy | D2: Type of Policy | E2: Beneficiary Name | G2: Cash Surrender Value | I2: Amount Borrowed | J2: Ownership
B8: =SUM(B4:C7) -> 0 | G8: =SUM(G4:H7) -> 0 | I8: =SUM(I4:I7) -> 0
A9: Disability Insurance | F9: Applicant | I9: Co-Applicant
A10: Monthly Distribution if Disabled
A11: Maximum Total Distribution
A13: Schedule C - Personal Residence, Real Estate Investments, and Mortgage Debt (majority ownership only)
A14: Personal Residence(s) - Please list each mortgage separately
A15: Property Address | B15: Legal Owner | C15: Purchase | E15: Market Value | F15: Present Balance | G15: Rate | H15: Maturity Date | I15: Monthly Payment | J15: Lender
C16: Date | D16: Price
A17: ='Page 1'!A10 -> 0 | I17: 1364.73
E24: =SUM(E17:E23) -> 0 | F24: =SUM(F17:F23) -> 0 | I24: =SUM(I17:I23) -> 1364.73
A25: Investment Properties - Please list each mortgage separately
A26: Property Address | B26: Legal Owner | C26: Purchase | E26: Market Value | F26: Present Balance | G26: Rate | H26: Maturity Date | I26: Monthly Payment | J26: Lender
C27: Date | D27: Price
A28: Please see attached SREO | E28: ='Page 6'!H46 -> 200000 | F28: ='Page 6'!I46 -> 0 | I28: ='Page 6'!N46 -> 8
A36: To list any additional residential or investment properties please provide an attachment to this form.
A37: Schedule D - Partnerships (including less than majority ownership for real estate partnerships*)
A38: Type of Investment | B38: Date of Initial Investment | D38: Cost | E38: Percent Owned | F38: Current Market Value | H38: Balance Due on Notes or Cash Calls | J38: Contribution Date
D39: Cost
F50: =SUM(F40:G49) -> 0 | H50: =SUM(H40:I49) -> 0
A51: *Note: For investments which represent a material portion of your total assets, please include the relevant financial statements or tax returns, or in the case of partnership investments or S-Corporations, schedule K-1s.

Sheet Page 4
A1: Schedule E - Notes Payable
A2: Due To: | B2: Type of Facility | C2: Amount | D2: Secured | F2: Collateral | G2: Interest Rate | H2: Maturity | I2: Unpaid Balance
D3: Yes | E3: No
I10: =SUM(I4:J9) -> 0
A12: Please answer all of the following questions:
G13: Yes | H13: No
A14: 1. Income tax returns are filed to __________________ (date) Are any returns being audited?
A15: 2. Have (either of) you, or any firm in which you were a major owner, ever declared bankruptcy?
A16: 3. Have (either of) you drawn a will? If so please furnish the executor's name(s) _____________________________
A17: 4. Please enter the number of your dependents and their relationship ______________________________________
A18: 5. Have (either of) you ever had a financial plan prepared for you?
A19: 6. Have you included the last two years federal and state tax returns with your financial statement?
A20: 7. Do (either of) you have a line of credit or unused credit facility at another financial institution?
A21: 8. Do (either of) you anticipate any substantial inheritances? If yes, please provide details.
A22: 9. Are (either of) you a partner or officer in any ventures? If yes please provide details.
A23: 10. Are (either of) your assets pledged other than described in this statement? If yes please provide details.
A26: Representations and Warranties
A48: _________________________ | B48: ='Page 1'!C13 -> 0
A49: Date | B49: Social Security No. | F49: Applicant Signature | G49: ='Page 1'!A8 -> 0
A51: _________________________ | B51: ='Page 1'!I13 -> 0
A52: Date | B52: Social Security No. | F52: Co-Applicant Signature | G52: ='Page 1'!G8 -> 0

Sheet Page 6
H1: SCHEDULE OF REAL ESTATE OWNED
A2: Borrower: | C2: ='Page 1'!A8 -> 0
A3: Proposed status changes in the near future (sale, exchange, rental composition, etc.) should be described in remarks section. | S3: Ownership Entity
A4: If percentage of ownership in any property is less than 100%, indicate other owners and their % in remarks section.
A5: Property Address | E5: Property | F5: % of | G5: Acq. Date | H5: Market | I5: Mortgage | J5: Date | K5: Name of | L5: Loan | M5: Monthly | N5: Mortgage | O5: Annual | Q5: Monthly | R5: Net
A6: Status | E6: Type | F6: Owrshp | G6: Cost | H6: Value | I6: Liens | J6: Loan Due | K6: Mortgage Lender | L6: Number | M6: Rents | N6: P & I | O6: Expenses | Q6: Expenses | R6: Income
F7: 1 | G7: Date: | H7: 200000 | I7: 1st: | M7: 100 | N7: 1 | O7: T: | P7: 1 | Q7: 3 | R7: =SUM(M7)-N7-N9-Q7 -> 96
I8: 0
B9: O/O | D9: Rental | G9: Cost: | I9: 2nd: | O9: I: | P9: 2
B10: PS | D10: Sold | I10: 0
F11: 1 | G11: Date: | I11: 1st: | M11: 5 | N11: 1 | O11: T: | P11: 1 | Q11: 0 | R11: =SUM(M11)-N11-N13-Q11 -> 4
I12: 0
B13: O/O | D13: Rental | G13: Cost: | I13: 2nd: | O13: I: | P13: 2
B14: PS | D14: Sold | I14: 0
F15: 1 | G15: Date: | I15: 1st: | M15: 10 | N15: 1 | O15: T: | P15: 1 | Q15: 0 | R15: =SUM(M15)-N15-N17-Q15 -> 9
I16: 0
B17: O/O | D17: Rental | G17: Cost: | I17: 2nd: | O17: I: | P17: 2
B18: PS | D18: Sold | I18: 0
F19: 1 | G19: Date: | I19: 1st: | M19: 500 | N19: 1 | O19: T: | P19: 1 | Q19: 0 | R19: =SUM(M19)-N19-N21-Q19 -> 499
I20: 0
B21: O/O | D21: Rental | G21: Cost: | I21: 2nd: | O21: I: | P21: 2
B22: PS | D22: Sold | I22: 0
F23: 1 | G23: Date: | I23: 1st: | M23: 10 | N23: 1 | O23: T: | P23: 1 | Q23: 0 | R23: =SUM(M23)-N23-N25-Q23 -> 9
I24: 0
B25: O/O | D25: Rental | G25: Cost: | I25: 2nd: | O25: I: | P25: 2
B26: PS | D26: Sold | I26: 0
F27: 1 | G27: Date: | I27: 1st: | M27: 10 | N27: 1 | O27: T: | P27: 1 | Q27: 0 | R27: =SUM(M27)-N27-N29-Q27 -> 9
I28: 0
B29: O/O | D29: Rental | G29: Cost: | I29: 2nd: | O29: I: | P29: 2
B30: PS | D30: Sold | I30: 0
F31: 1 | G31: Date: | I31: 1st: | M31: 10 | N31: 1 | O31: T: | P31: 1 | Q31: 0 | R31: =SUM(M31)-N31-N33-Q31 -> 9
I32: 0
B33: O/O | D33: Rental | G33: Cost: | I33: 2nd: | O33: I: | P33: 2
B34: PS | D34: Sold | I34: 0
F35: 1 | G35: Date: | I35: 1st: | M35: 10 | N35: 1 | O35: T: | P35: 1 | Q35: 0 | R35: =SUM(M35)-N35-N37-Q35 -> 9
I36: 0
B37: O/O | D37: Rental | G37: Cost: | I37: 2nd: | O37: I: | P37: 2
B38: PS | D38: Sold | I38: 0
F39: 1 | G39: Date: | I39: 1st: | M39: 10 | N39: 1 | O39: T: | P39: 1 | Q39: 0 | R39: =SUM(M39)-N39-N41-Q39 -> 9
I40: 0
...

Sheet Page 6 (2)
H1: SCHEDULE OF REAL ESTATE OWNED
A2: Borrower: | C2: ='Page 1'!A8 -> 0
A3: Proposed status changes in the near future (sale, exchange, rental composition, etc.) should be described in remarks section. | S3: Ownership Entity
A4: If percentage of ownership in any property is less than 100%, indicate other owners and their % in remarks section.
A5: Property Address | E5: Property | F5: % of | G5: Acq. Date | H5: Market | I5: Mortgage | J5: Date | K5: Name of | L5: Loan | M5: Monthly | N5: Mortgage | O5: Annual | Q5: Monthly | R5: Net
A6: Status | E6: Type | F6: Owrshp | G6: Cost | H6: Value | I6: Liens | J6: Loan Due | K6: Mortgage Lender | L6: Number | M6: Rents | N6: P & I | O6: Expenses | Q6: Expenses | R6: Income
F7: 1 | G7: Date: | I7: 1st: | M7: 1000 | N7: 0 | O7: T: | P7: 8500 | Q7: =SUM(P7:P10)/12 -> 791.66667 | R7: =SUM(M7)-N7-N9-Q7 -> 208.33333
I8: 0
B9: O/O | D9: Rental | G9: Cost: | I9: 2nd: | O9: I: | P9: 1000
B10: PS | D10: Sold | I10: 0
F11: 1 | G11: Date: | I11: 1st: | N11: 0 | O11: T: | Q11: =SUM(P11:P14)/12 -> 0 | R11: =SUM(M11)-N11-N13-Q11 -> 0
I12: 0
B13: O/O | D13: Rental | G13: Cost: | I13: 2nd: | O13: I:
B14: PS | D14: Sold | I14: 0
F15: 1 | G15: Date: | I15: 1st: | N15: 0 | O15: T: | Q15: =SUM(P15:P18)/12 -> 0 | R15: =SUM(M15)-N15-N17-Q15 -> 0
I16: 0
B17: O/O | D17: Rental | G17: Cost: | I17: 2nd: | O17: I:
B18: PS | D18: Sold | I18: 0
F19: 1 | G19: Date: | I19: 1st: | N19: 0 | O19: T: | Q19: =SUM(P19:P22)/12 -> 0 | R19: =SUM(M19)-N19-N21-Q19 -> 0
I20: 0
B21: O/O | D21: Rental | G21: Cost: | I21: 2nd: | O21: I:
B22: PS | D22: Sold | I22: 0
F23: 1 | G23: Date: | I23: 1st: | N23: 0 | O23: T: | Q23: =SUM(P23:P26)/12 -> 0 | R23: =SUM(M23)-N23-N25-Q23 -> 0
I24: 0
B25: O/O | D25: Rental | G25: Cost: | I25: 2nd: | O25: I:
B26: PS | D26: Sold | I26: 0
F27: 1 | G27: Date: | I27: 1st: | N27: 0 | O27: T: | Q27: =SUM(P27:P30)/12 -> 0 | R27: =SUM(M27)-N27-N29-Q27 -> 0
I28: 0
B29: O/O | D29: Rental | G29: Cost: | I29: 2nd: | O29: I:
B30: PS | D30: Sold | I30: 0
F31: 1 | G31: Date: | I31: 1st: | N31: 0 | O31: T: | Q31: =SUM(P31:P34)/12 -> 0 | R31: =SUM(M31)-N31-N33-Q31 -> 0
I32: 0
B33: O/O | D33: Rental | G33: Cost: | I33: 2nd: | O33: I:
B34: PS | D34: Sold | I34: 0
F35: 1 | G35: Date: | I35: 1st: | N35: 0 | O35: T: | Q35: =SUM(P35:P38)/12 -> 0 | R35: =SUM(M35)-N35-N37-Q35 -> 0
I36: 0
B37: O/O | D37: Rental | G37: Cost: | I37: 2nd: | O37: I:
B38: PS | D38: Sold | I38: 0
F39: 1 | G39: Date: | I39: 1st: | N39: 0 | O39: T: | Q39: =SUM(P39:P42)/12 -> 0 | R39: =SUM(M39)-N39-N41-Q39 -> 0
I40: 0
...

Sheet Page 6 (3)
H1: SCHEDULE OF REAL ESTATE OWNED
A2: Borrower: | C2: ='Page 1'!A8 -> 0
A3: Proposed status changes in the near future (sale, exchange, rental composition, etc.) should be described in remarks section. | S3: Ownership Entity
A4: If percentage of ownership in any property is less than 100%, indicate other owners and their % in remarks section.
A5: Property Address | E5: Property | F5: % of | G5: Acq. Date | H5: Market | I5: Mortgage | J5: Date | K5: Name of | L5: Loan | M5: Monthly | N5: Mortgage | O5: Annual | Q5: Monthly | R5: Net
A6: Status | E6: Type | F6: Owrshp | G6: Cost | H6: Value | I6: Liens | J6: Loan Due | K6: Mortgage Lender | L6: Number | M6: Rents | N6: P & I | O6: Expenses | Q6: Expenses | R6: Income
F7: 1 | G7: Date: | I7: 1st: | N7: 0 | O7: T: | Q7: =SUM(P7:P10)/12 -> 0 | R7: =SUM(M7)-N7-N9-Q7 -> 0
I8: 0
B9: O/O | D9: Rental | G9: Cost: | I9: 2nd: | O9: I:
B10: PS | D10: Sold | I10: 0
F11: 1 | G11: Date: | I11: 1st: | N11: 0 | O11: T: | Q11: =SUM(P11:P14)/12 -> 0 | R11: =SUM(M11)-N11-N13-Q11 -> 0
I12: 0
B13: O/O | D13: Rental | G13: Cost: | I13: 2nd: | O13: I:
B14: PS | D14: Sold | I14: 0
F15: 1 | G15: Date: | I15: 1st: | M15: 1000 | N15: 0 | O15: T: | P15: 6000 | Q15: =SUM(P15:P18)/12 -> 583.33333 | R15: =SUM(M15)-N15-N17-Q15 -> 416.66667
I16: 0
B17: O/O | D17: Rental | G17: Cost: | I17: 2nd: | O17: I: | P17: 1000
B18: PS | D18: Sold | I18: 0
F19: 1 | G19: Date: | I19: 1st: | N19: 0 | O19: T: | Q19: =SUM(P19:P22)/12 -> 0 | R19: =SUM(M19)-N19-N21-Q19 -> 0
I20: 0
B21: O/O | D21: Rental | G21: Cost: | I21: 2nd: | O21: I:
B22: PS | D22: Sold | I22: 0
F23: 1 | G23: Date: | I23: 1st: | N23: 0 | O23: T: | Q23: =SUM(P23:P26)/12 -> 0 | R23: =SUM(M23)-N23-N25-Q23 -> 0
I24: 0
B25: O/O | D25: Rental | G25: Cost: | I25: 2nd: | O25: I:
B26: PS | D26: Sold | I26: 0
F27: 1 | G27: Date: | I27: 1st: | N27: 0 | O27: T: | Q27: =SUM(P27:P30)/12 -> 0 | R27: =SUM(M27)-N27-N29-Q27 -> 0
I28: 0
B29: O/O | D29: Rental | G29: Cost: | I29: 2nd: | O29: I:
B30: PS | D30: Sold | I30: 0
F31: 1 | G31: Date: | I31: 1st: | N31: 0 | O31: T: | Q31: =SUM(P31:P34)/12 -> 0 | R31: =SUM(M31)-N31-N33-Q31 -> 0
I32: 0
B33: O/O | D33: Rental | G33: Cost: | I33: 2nd: | O33: I:
B34: PS | D34: Sold | I34: 0
F35: 1 | G35: Date: | I35: 1st: | N35: 0 | O35: T: | Q35: =SUM(P35:P38)/12 -> 0 | R35: =SUM(M35)-N35-N37-Q35 -> 0
I36: 0
B37: O/O | D37: Rental | G37: Cost: | I37: 2nd: | O37: I:
B38: PS | D38: Sold | I38: 0
F39: 1 | G39: Date: | I39: 1st: | N39: 0 | O39: T: | Q39: =SUM(P39:P42)/12 -> 0 | R39: =SUM(M39)-N39-N41-Q39 -> 0
I40: 0
...
